/g/data3/hh5/public/apps/miniconda3/envs/analysis3-19.07/lib/python3.6/site-packages/xarray/core/nanops.py:140: RuntimeWarning: Mean of empty slice
  return np.nanmean(a, axis=axis, dtype=dtype)
Traceback (most recent call last):
  File "/g/data3/hh5/public/apps/miniconda3/envs/analysis3-19.07/lib/python3.6/site-packages/xarray/core/common.py", line 169, in _get_axis_num
    return self.dims.index(dim)
ValueError: tuple.index(x): x not in tuple

During handling of the above exception, another exception occurred:

Traceback (most recent call last):
  File "/g/data/e14/as3189/OFAM/scripts/plot_velocity.py", line 101, in <module>
    plot_EUC_mon_profile(dh, exp=0)
  File "/g/data/e14/as3189/OFAM/scripts/plot_velocity.py", line 85, in plot_EUC_mon_profile
    cs = plt.pcolormesh(Y, Z, ds.sel(xu_ocean=x).mean('mon'), 
  File "/g/data3/hh5/public/apps/miniconda3/envs/analysis3-19.07/lib/python3.6/site-packages/xarray/core/common.py", line 47, in wrapped_func
    func, dim, axis, skipna=skipna, allow_lazy=True, **kwargs
  File "/g/data3/hh5/public/apps/miniconda3/envs/analysis3-19.07/lib/python3.6/site-packages/xarray/core/dataarray.py", line 2131, in reduce
    var = self.variable.reduce(func, dim, axis, keep_attrs, keepdims, **kwargs)
  File "/g/data3/hh5/public/apps/miniconda3/envs/analysis3-19.07/lib/python3.6/site-packages/xarray/core/variable.py", line 1446, in reduce
    axis = self.get_axis_num(dim)
  File "/g/data3/hh5/public/apps/miniconda3/envs/analysis3-19.07/lib/python3.6/site-packages/xarray/core/common.py", line 165, in get_axis_num
    return self._get_axis_num(dim)
  File "/g/data3/hh5/public/apps/miniconda3/envs/analysis3-19.07/lib/python3.6/site-packages/xarray/core/common.py", line 171, in _get_axis_num
    raise ValueError("%r not found in array dimensions %r" % (dim, self.dims))
ValueError: 'mon' not found in array dimensions ('month', 'st_ocean', 'yu_ocean')
