Traceback (most recent call last):
  File "/g/data3/hh5/public/apps/miniconda3/envs/analysis3-20.01/lib/python3.7/site-packages/xarray/backends/file_manager.py", line 198, in _acquire_with_cache_info
    file = self._cache[self._key]
  File "/g/data3/hh5/public/apps/miniconda3/envs/analysis3-20.01/lib/python3.7/site-packages/xarray/backends/lru_cache.py", line 53, in __getitem__
    value = self._cache[key]
KeyError: [<class 'netCDF4._netCDF4.Dataset'>, ('/g/data1/ua8/JRA55-do/latest/u_10.1981.nc',), 'r', (('clobber', True), ('diskless', False), ('format', 'NETCDF4'), ('persist', False))]

During handling of the above exception, another exception occurred:

Traceback (most recent call last):
  File "/g/data/e14/as3189/OFAM/scripts/create_file_wsc.py", line 100, in <module>
    du = xr.open_mfdataset(u, combine='by_coords')
  File "/g/data3/hh5/public/apps/miniconda3/envs/analysis3-20.01/lib/python3.7/site-packages/xarray/backends/api.py", line 908, in open_mfdataset
    datasets = [open_(p, **open_kwargs) for p in paths]
  File "/g/data3/hh5/public/apps/miniconda3/envs/analysis3-20.01/lib/python3.7/site-packages/xarray/backends/api.py", line 908, in <listcomp>
    datasets = [open_(p, **open_kwargs) for p in paths]
  File "/g/data3/hh5/public/apps/miniconda3/envs/analysis3-20.01/lib/python3.7/site-packages/xarray/backends/api.py", line 502, in open_dataset
    filename_or_obj, group=group, lock=lock, **backend_kwargs
  File "/g/data3/hh5/public/apps/miniconda3/envs/analysis3-20.01/lib/python3.7/site-packages/xarray/backends/netCDF4_.py", line 358, in open
    return cls(manager, group=group, mode=mode, lock=lock, autoclose=autoclose)
  File "/g/data3/hh5/public/apps/miniconda3/envs/analysis3-20.01/lib/python3.7/site-packages/xarray/backends/netCDF4_.py", line 314, in __init__
    self.format = self.ds.data_model
  File "/g/data3/hh5/public/apps/miniconda3/envs/analysis3-20.01/lib/python3.7/site-packages/xarray/backends/netCDF4_.py", line 367, in ds
    return self._acquire()
  File "/g/data3/hh5/public/apps/miniconda3/envs/analysis3-20.01/lib/python3.7/site-packages/xarray/backends/netCDF4_.py", line 361, in _acquire
    with self._manager.acquire_context(needs_lock) as root:
  File "/g/data3/hh5/public/apps/miniconda3/envs/analysis3-20.01/lib/python3.7/contextlib.py", line 112, in __enter__
    return next(self.gen)
  File "/g/data3/hh5/public/apps/miniconda3/envs/analysis3-20.01/lib/python3.7/site-packages/xarray/backends/file_manager.py", line 186, in acquire_context
    file, cached = self._acquire_with_cache_info(needs_lock)
  File "/g/data3/hh5/public/apps/miniconda3/envs/analysis3-20.01/lib/python3.7/site-packages/xarray/backends/file_manager.py", line 204, in _acquire_with_cache_info
    file = self._opener(*self._args, **kwargs)
  File "netCDF4/_netCDF4.pyx", line 2321, in netCDF4._netCDF4.Dataset.__init__
  File "netCDF4/_netCDF4.pyx", line 1885, in netCDF4._netCDF4._ensure_nc_success
FileNotFoundError: [Errno 2] No such file or directory: b'/g/data1/ua8/JRA55-do/latest/u_10.1981.nc'
