sh: None: command not found
INFO: Compiled ParcelsRandom ==> /jobfs/26972610.gadi-pbs/parcels-12904/libparcels_random_e894e025-c36e-4c56-ae74-c83f9a2fed7d.so
Starting plx_sources_rcp_220_v1...
Traceback (most recent call last):
  File "/g/data3/hh5/public/apps/miniconda3/envs/analysis3-21.04/lib/python3.8/site-packages/xarray/backends/file_manager.py", line 199, in _acquire_with_cache_info
    file = self._cache[self._key]
  File "/g/data3/hh5/public/apps/miniconda3/envs/analysis3-21.04/lib/python3.8/site-packages/xarray/backends/lru_cache.py", line 53, in __getitem__
    value = self._cache[key]
KeyError: [<class 'h5netcdf.core.File'>, ('/g/data/e14/as3189/OFAM/data/v1y/plx_rcp_220_v1_2075.nc',), 'r', (('decode_vlen_strings', True), ('invalid_netcdf', None))]

During handling of the above exception, another exception occurred:

Traceback (most recent call last):
  File "/g/data/e14/as3189/OFAM/scripts/plx_sources.py", line 126, in <module>
    plx_source_transit(args.lon, args.exp, v=1)
  File "/g/data/e14/as3189/OFAM/scripts/plx_sources.py", line 92, in plx_source_transit
    traj_size = find_max_traj(lon, exp, v)
  File "/g/data/e14/as3189/OFAM/scripts/plx_sources.py", line 36, in find_max_traj
    ds = xr.open_dataset(str(xid), mask_and_scale=True, engine='h5netcdf')
  File "/g/data3/hh5/public/apps/miniconda3/envs/analysis3-21.04/lib/python3.8/site-packages/xarray/backends/api.py", line 496, in open_dataset
    backend_ds = backend.open_dataset(
  File "/g/data3/hh5/public/apps/miniconda3/envs/analysis3-21.04/lib/python3.8/site-packages/xarray/backends/h5netcdf_.py", line 372, in open_dataset
    store = H5NetCDFStore.open(
  File "/g/data3/hh5/public/apps/miniconda3/envs/analysis3-21.04/lib/python3.8/site-packages/xarray/backends/h5netcdf_.py", line 178, in open
    return cls(manager, group=group, mode=mode, lock=lock, autoclose=autoclose)
  File "/g/data3/hh5/public/apps/miniconda3/envs/analysis3-21.04/lib/python3.8/site-packages/xarray/backends/h5netcdf_.py", line 123, in __init__
    self._filename = find_root_and_group(self.ds)[0].filename
  File "/g/data3/hh5/public/apps/miniconda3/envs/analysis3-21.04/lib/python3.8/site-packages/xarray/backends/h5netcdf_.py", line 189, in ds
    return self._acquire()
  File "/g/data3/hh5/public/apps/miniconda3/envs/analysis3-21.04/lib/python3.8/site-packages/xarray/backends/h5netcdf_.py", line 181, in _acquire
    with self._manager.acquire_context(needs_lock) as root:
  File "/g/data3/hh5/public/apps/miniconda3/envs/analysis3-21.04/lib/python3.8/contextlib.py", line 113, in __enter__
    return next(self.gen)
  File "/g/data3/hh5/public/apps/miniconda3/envs/analysis3-21.04/lib/python3.8/site-packages/xarray/backends/file_manager.py", line 187, in acquire_context
    file, cached = self._acquire_with_cache_info(needs_lock)
  File "/g/data3/hh5/public/apps/miniconda3/envs/analysis3-21.04/lib/python3.8/site-packages/xarray/backends/file_manager.py", line 205, in _acquire_with_cache_info
    file = self._opener(*self._args, **kwargs)
  File "/g/data3/hh5/public/apps/miniconda3/envs/analysis3-21.04/lib/python3.8/site-packages/h5netcdf/core.py", line 779, in __init__
    self._all_h5groups = ChainMap(self._h5group)
  File "/g/data3/hh5/public/apps/miniconda3/envs/analysis3-21.04/lib/python3.8/site-packages/h5netcdf/core.py", line 391, in _h5group
    return self._root._h5file[self._h5path]
  File "h5py/_objects.pyx", line 54, in h5py._objects.with_phil.wrapper
  File "h5py/_objects.pyx", line 55, in h5py._objects.with_phil.wrapper
  File "/g/data3/hh5/public/apps/miniconda3/envs/analysis3-21.04/lib/python3.8/site-packages/h5py/_hl/group.py", line 305, in __getitem__
    oid = h5o.open(self.id, self._e(name), lapl=self._lapl)
  File "h5py/_objects.pyx", line 54, in h5py._objects.with_phil.wrapper
  File "h5py/_objects.pyx", line 55, in h5py._objects.with_phil.wrapper
  File "h5py/h5o.pyx", line 190, in h5py.h5o.open
KeyError: 'Unable to open object (incorrect metadatda checksum after all read attempts)'
