sh: None: command not found
INFO: Compiled ParcelsRandom ==> /jobfs/26520720.gadi-pbs/parcels-12904/libparcels_random_eea6bd72-86a7-4416-9387-e07dcab42bba.so
Subsetting by year plx_hist_250_v1.
plx_hist_250_v1: Opening subset of data.
Traceback (most recent call last):
  File "/g/data3/hh5/public/apps/miniconda3/envs/analysis3-21.04/lib/python3.8/site-packages/xarray/backends/file_manager.py", line 199, in _acquire_with_cache_info
    file = self._cache[self._key]
  File "/g/data3/hh5/public/apps/miniconda3/envs/analysis3-21.04/lib/python3.8/site-packages/xarray/backends/lru_cache.py", line 53, in __getitem__
    value = self._cache[key]
KeyError: [<class 'netCDF4._netCDF4.Dataset'>, ('/g/data/e14/as3189/OFAM/data/v1/plx_hist_250_v1r09.nc',), 'r', (('clobber', True), ('diskless', False), ('format', 'NETCDF4'), ('persist', False))]

During handling of the above exception, another exception occurred:

Traceback (most recent call last):
  File "/g/data/e14/as3189/OFAM/scripts/split_plx_files.py", line 97, in <module>
    save_particle_data_by_year(args.lon, args.exp, v=1, r_range=[0, 10])
  File "/g/data/e14/as3189/OFAM/scripts/split_plx_files.py", line 62, in save_particle_data_by_year
    dx = xr.combine_nested([open_plx_data(xid, drop_variables=drop_vars).isel(obs=0) for xid in xids],
  File "/g/data/e14/as3189/OFAM/scripts/split_plx_files.py", line 62, in <listcomp>
    dx = xr.combine_nested([open_plx_data(xid, drop_variables=drop_vars).isel(obs=0) for xid in xids],
  File "/g/data/e14/as3189/OFAM/scripts/main.py", line 364, in open_plx_data
    ds = xr.open_dataset(str(xid), mask_and_scale=True, **kwargs)
  File "/g/data3/hh5/public/apps/miniconda3/envs/analysis3-21.04/lib/python3.8/site-packages/xarray/backends/api.py", line 496, in open_dataset
    backend_ds = backend.open_dataset(
  File "/g/data3/hh5/public/apps/miniconda3/envs/analysis3-21.04/lib/python3.8/site-packages/xarray/backends/netCDF4_.py", line 549, in open_dataset
    store = NetCDF4DataStore.open(
  File "/g/data3/hh5/public/apps/miniconda3/envs/analysis3-21.04/lib/python3.8/site-packages/xarray/backends/netCDF4_.py", line 380, in open
    return cls(manager, group=group, mode=mode, lock=lock, autoclose=autoclose)
  File "/g/data3/hh5/public/apps/miniconda3/envs/analysis3-21.04/lib/python3.8/site-packages/xarray/backends/netCDF4_.py", line 328, in __init__
    self.format = self.ds.data_model
  File "/g/data3/hh5/public/apps/miniconda3/envs/analysis3-21.04/lib/python3.8/site-packages/xarray/backends/netCDF4_.py", line 389, in ds
    return self._acquire()
  File "/g/data3/hh5/public/apps/miniconda3/envs/analysis3-21.04/lib/python3.8/site-packages/xarray/backends/netCDF4_.py", line 383, in _acquire
    with self._manager.acquire_context(needs_lock) as root:
  File "/g/data3/hh5/public/apps/miniconda3/envs/analysis3-21.04/lib/python3.8/contextlib.py", line 113, in __enter__
    return next(self.gen)
  File "/g/data3/hh5/public/apps/miniconda3/envs/analysis3-21.04/lib/python3.8/site-packages/xarray/backends/file_manager.py", line 187, in acquire_context
    file, cached = self._acquire_with_cache_info(needs_lock)
  File "/g/data3/hh5/public/apps/miniconda3/envs/analysis3-21.04/lib/python3.8/site-packages/xarray/backends/file_manager.py", line 205, in _acquire_with_cache_info
    file = self._opener(*self._args, **kwargs)
  File "src/netCDF4/_netCDF4.pyx", line 2330, in netCDF4._netCDF4.Dataset.__init__
  File "src/netCDF4/_netCDF4.pyx", line 1948, in netCDF4._netCDF4._ensure_nc_success
FileNotFoundError: [Errno 2] No such file or directory: b'/g/data/e14/as3189/OFAM/data/v1/plx_hist_250_v1r09.nc'
