ofam_u_month_anom_r1.nc: Rank=1: Starting.
ofam_u_month_anom_r4.nc: Rank=4: Starting.
ofam_u_month_anom_r5.nc: Rank=5: Starting.
ofam_u_month_anom_r7.nc: Rank=7: Starting.
ofam_u_month_anom_r3.nc: Rank=3: Starting.
ofam_u_month_anom_r2.nc: Rank=2: Starting.
ofam_u_month_anom_r0.nc: Rank=0: Starting.
ofam_u_month_anom_r6.nc: Rank=6: Starting.
Traceback (most recent call last):
  File "/g/data3/hh5/public/apps/miniconda3/envs/analysis3-21.01/lib/python3.8/site-packages/xarray/core/dataset.py", line 1259, in _construct_dataarray
    variable = self._variables[name]
KeyError: 'Time.month'

During handling of the above exception, another exception occurred:

Traceback (most recent call last):
  File "/g/data/e14/as3189/OFAM/scripts/create_file_ofam_EUC_anom_std.py", line 43, in <module>
    ds = xr.open_mfdataset(files, combine='by_coords', concat_dim="Time",
  File "/g/data3/hh5/public/apps/miniconda3/envs/analysis3-21.01/lib/python3.8/site-packages/xarray/backends/api.py", line 956, in open_mfdataset
    datasets, file_objs = dask.compute(datasets, file_objs)
  File "/g/data3/hh5/public/apps/miniconda3/envs/analysis3-21.01/lib/python3.8/site-packages/dask/base.py", line 563, in compute
    results = schedule(dsk, keys, **kwargs)
  File "/g/data3/hh5/public/apps/miniconda3/envs/analysis3-21.01/lib/python3.8/site-packages/dask/threaded.py", line 76, in get
    results = get_async(
  File "/g/data3/hh5/public/apps/miniconda3/envs/analysis3-21.01/lib/python3.8/site-packages/dask/local.py", line 487, in get_async
    raise_exception(exc, tb)
  File "/g/data3/hh5/public/apps/miniconda3/envs/analysis3-21.01/lib/python3.8/site-packages/dask/local.py", line 317, in reraise
    raise exc
  File "/g/data3/hh5/public/apps/miniconda3/envs/analysis3-21.01/lib/python3.8/site-packages/dask/local.py", line 222, in execute_task
    result = _execute_task(task, data)
  File "/g/data3/hh5/public/apps/miniconda3/envs/analysis3-21.01/lib/python3.8/site-packages/dask/core.py", line 121, in _execute_task
    return func(*(_execute_task(a, cache) for a in args))
  File "/g/data/e14/as3189/OFAM/scripts/create_file_ofam_EUC_anom_std.py", line 37, in premeansnip
    ds = ds.groupby('Time.month') - clim.groupby('Time.month').mean('Time', keep_attrs=True).compute()
  File "/g/data3/hh5/public/apps/miniconda3/envs/analysis3-21.01/lib/python3.8/site-packages/xarray/core/common.py", line 696, in groupby
    return self._groupby_cls(
  File "/g/data3/hh5/public/apps/miniconda3/envs/analysis3-21.01/lib/python3.8/site-packages/xarray/core/groupby.py", line 315, in __init__
    group = obj[group]
  File "/g/data3/hh5/public/apps/miniconda3/envs/analysis3-21.01/lib/python3.8/site-packages/xarray/core/dataset.py", line 1359, in __getitem__
    return self._construct_dataarray(key)
  File "/g/data3/hh5/public/apps/miniconda3/envs/analysis3-21.01/lib/python3.8/site-packages/xarray/core/dataset.py", line 1261, in _construct_dataarray
    _, name, variable = _get_virtual_variable(
  File "/g/data3/hh5/public/apps/miniconda3/envs/analysis3-21.01/lib/python3.8/site-packages/xarray/core/dataset.py", line 171, in _get_virtual_variable
    ref_var = variables[ref_name]
KeyError: 'Time'
Traceback (most recent call last):
  File "/g/data3/hh5/public/apps/miniconda3/envs/analysis3-21.01/lib/python3.8/site-packages/xarray/core/dataset.py", line 1259, in _construct_dataarray
    variable = self._variables[name]
KeyError: 'Time.month'

During handling of the above exception, another exception occurred:

Traceback (most recent call last):
  File "/g/data/e14/as3189/OFAM/scripts/create_file_ofam_EUC_anom_std.py", line 43, in <module>
    ds = xr.open_mfdataset(files, combine='by_coords', concat_dim="Time",
  File "/g/data3/hh5/public/apps/miniconda3/envs/analysis3-21.01/lib/python3.8/site-packages/xarray/backends/api.py", line 956, in open_mfdataset
    datasets, file_objs = dask.compute(datasets, file_objs)
  File "/g/data3/hh5/public/apps/miniconda3/envs/analysis3-21.01/lib/python3.8/site-packages/dask/base.py", line 563, in compute
    results = schedule(dsk, keys, **kwargs)
  File "/g/data3/hh5/public/apps/miniconda3/envs/analysis3-21.01/lib/python3.8/site-packages/dask/threaded.py", line 76, in get
    results = get_async(
  File "/g/data3/hh5/public/apps/miniconda3/envs/analysis3-21.01/lib/python3.8/site-packages/dask/local.py", line 487, in get_async
    raise_exception(exc, tb)
  File "/g/data3/hh5/public/apps/miniconda3/envs/analysis3-21.01/lib/python3.8/site-packages/dask/local.py", line 317, in reraise
    raise exc
  File "/g/data3/hh5/public/apps/miniconda3/envs/analysis3-21.01/lib/python3.8/site-packages/dask/local.py", line 222, in execute_task
    result = _execute_task(task, data)
  File "/g/data3/hh5/public/apps/miniconda3/envs/analysis3-21.01/lib/python3.8/site-packages/dask/core.py", line 121, in _execute_task
    return func(*(_execute_task(a, cache) for a in args))
  File "/g/data/e14/as3189/OFAM/scripts/create_file_ofam_EUC_anom_std.py", line 37, in premeansnip
    ds = ds.groupby('Time.month') - clim.groupby('Time.month').mean('Time', keep_attrs=True).compute()
  File "/g/data3/hh5/public/apps/miniconda3/envs/analysis3-21.01/lib/python3.8/site-packages/xarray/core/common.py", line 696, in groupby
    return self._groupby_cls(
  File "/g/data3/hh5/public/apps/miniconda3/envs/analysis3-21.01/lib/python3.8/site-packages/xarray/core/groupby.py", line 315, in __init__
    group = obj[group]
  File "/g/data3/hh5/public/apps/miniconda3/envs/analysis3-21.01/lib/python3.8/site-packages/xarray/core/dataset.py", line 1359, in __getitem__
    return self._construct_dataarray(key)
  File "/g/data3/hh5/public/apps/miniconda3/envs/analysis3-21.01/lib/python3.8/site-packages/xarray/core/dataset.py", line 1261, in _construct_dataarray
    _, name, variable = _get_virtual_variable(
  File "/g/data3/hh5/public/apps/miniconda3/envs/analysis3-21.01/lib/python3.8/site-packages/xarray/core/dataset.py", line 171, in _get_virtual_variable
    ref_var = variables[ref_name]
KeyError: 'Time'
Traceback (most recent call last):
  File "/g/data3/hh5/public/apps/miniconda3/envs/analysis3-21.01/lib/python3.8/site-packages/xarray/core/dataset.py", line 1259, in _construct_dataarray
    variable = self._variables[name]
KeyError: 'Time.month'

During handling of the above exception, another exception occurred:

Traceback (most recent call last):
  File "/g/data/e14/as3189/OFAM/scripts/create_file_ofam_EUC_anom_std.py", line 43, in <module>
    ds = xr.open_mfdataset(files, combine='by_coords', concat_dim="Time",
  File "/g/data3/hh5/public/apps/miniconda3/envs/analysis3-21.01/lib/python3.8/site-packages/xarray/backends/api.py", line 956, in open_mfdataset
    datasets, file_objs = dask.compute(datasets, file_objs)
  File "/g/data3/hh5/public/apps/miniconda3/envs/analysis3-21.01/lib/python3.8/site-packages/dask/base.py", line 563, in compute
    results = schedule(dsk, keys, **kwargs)
  File "/g/data3/hh5/public/apps/miniconda3/envs/analysis3-21.01/lib/python3.8/site-packages/dask/threaded.py", line 76, in get
    results = get_async(
  File "/g/data3/hh5/public/apps/miniconda3/envs/analysis3-21.01/lib/python3.8/site-packages/dask/local.py", line 487, in get_async
    raise_exception(exc, tb)
  File "/g/data3/hh5/public/apps/miniconda3/envs/analysis3-21.01/lib/python3.8/site-packages/dask/local.py", line 317, in reraise
    raise exc
  File "/g/data3/hh5/public/apps/miniconda3/envs/analysis3-21.01/lib/python3.8/site-packages/dask/local.py", line 222, in execute_task
    result = _execute_task(task, data)
  File "/g/data3/hh5/public/apps/miniconda3/envs/analysis3-21.01/lib/python3.8/site-packages/dask/core.py", line 121, in _execute_task
    return func(*(_execute_task(a, cache) for a in args))
  File "/g/data/e14/as3189/OFAM/scripts/create_file_ofam_EUC_anom_std.py", line 37, in premeansnip
    ds = ds.groupby('Time.month') - clim.groupby('Time.month').mean('Time', keep_attrs=True).compute()
  File "/g/data3/hh5/public/apps/miniconda3/envs/analysis3-21.01/lib/python3.8/site-packages/xarray/core/common.py", line 696, in groupby
    return self._groupby_cls(
  File "/g/data3/hh5/public/apps/miniconda3/envs/analysis3-21.01/lib/python3.8/site-packages/xarray/core/groupby.py", line 315, in __init__
    group = obj[group]
  File "/g/data3/hh5/public/apps/miniconda3/envs/analysis3-21.01/lib/python3.8/site-packages/xarray/core/dataset.py", line 1359, in __getitem__
    return self._construct_dataarray(key)
  File "/g/data3/hh5/public/apps/miniconda3/envs/analysis3-21.01/lib/python3.8/site-packages/xarray/core/dataset.py", line 1261, in _construct_dataarray
    _, name, variable = _get_virtual_variable(
  File "/g/data3/hh5/public/apps/miniconda3/envs/analysis3-21.01/lib/python3.8/site-packages/xarray/core/dataset.py", line 171, in _get_virtual_variable
    ref_var = variables[ref_name]
KeyError: 'Time'
Traceback (most recent call last):
  File "/g/data3/hh5/public/apps/miniconda3/envs/analysis3-21.01/lib/python3.8/site-packages/xarray/core/dataset.py", line 1259, in _construct_dataarray
    variable = self._variables[name]
KeyError: 'Time.month'

During handling of the above exception, another exception occurred:

Traceback (most recent call last):
  File "/g/data/e14/as3189/OFAM/scripts/create_file_ofam_EUC_anom_std.py", line 43, in <module>
    ds = xr.open_mfdataset(files, combine='by_coords', concat_dim="Time",
  File "/g/data3/hh5/public/apps/miniconda3/envs/analysis3-21.01/lib/python3.8/site-packages/xarray/backends/api.py", line 956, in open_mfdataset
    datasets, file_objs = dask.compute(datasets, file_objs)
  File "/g/data3/hh5/public/apps/miniconda3/envs/analysis3-21.01/lib/python3.8/site-packages/dask/base.py", line 563, in compute
    results = schedule(dsk, keys, **kwargs)
  File "/g/data3/hh5/public/apps/miniconda3/envs/analysis3-21.01/lib/python3.8/site-packages/dask/threaded.py", line 76, in get
    results = get_async(
  File "/g/data3/hh5/public/apps/miniconda3/envs/analysis3-21.01/lib/python3.8/site-packages/dask/local.py", line 487, in get_async
    raise_exception(exc, tb)
  File "/g/data3/hh5/public/apps/miniconda3/envs/analysis3-21.01/lib/python3.8/site-packages/dask/local.py", line 317, in reraise
    raise exc
  File "/g/data3/hh5/public/apps/miniconda3/envs/analysis3-21.01/lib/python3.8/site-packages/dask/local.py", line 222, in execute_task
    result = _execute_task(task, data)
  File "/g/data3/hh5/public/apps/miniconda3/envs/analysis3-21.01/lib/python3.8/site-packages/dask/core.py", line 121, in _execute_task
    return func(*(_execute_task(a, cache) for a in args))
  File "/g/data/e14/as3189/OFAM/scripts/create_file_ofam_EUC_anom_std.py", line 37, in premeansnip
    ds = ds.groupby('Time.month') - clim.groupby('Time.month').mean('Time', keep_attrs=True).compute()
  File "/g/data3/hh5/public/apps/miniconda3/envs/analysis3-21.01/lib/python3.8/site-packages/xarray/core/common.py", line 696, in groupby
    return self._groupby_cls(
  File "/g/data3/hh5/public/apps/miniconda3/envs/analysis3-21.01/lib/python3.8/site-packages/xarray/core/groupby.py", line 315, in __init__
    group = obj[group]
  File "/g/data3/hh5/public/apps/miniconda3/envs/analysis3-21.01/lib/python3.8/site-packages/xarray/core/dataset.py", line 1359, in __getitem__
    return self._construct_dataarray(key)
  File "/g/data3/hh5/public/apps/miniconda3/envs/analysis3-21.01/lib/python3.8/site-packages/xarray/core/dataset.py", line 1261, in _construct_dataarray
    _, name, variable = _get_virtual_variable(
  File "/g/data3/hh5/public/apps/miniconda3/envs/analysis3-21.01/lib/python3.8/site-packages/xarray/core/dataset.py", line 171, in _get_virtual_variable
    ref_var = variables[ref_name]
KeyError: 'Time'
Traceback (most recent call last):
  File "/g/data3/hh5/public/apps/miniconda3/envs/analysis3-21.01/lib/python3.8/site-packages/xarray/core/dataset.py", line 1259, in _construct_dataarray
    variable = self._variables[name]
KeyError: 'Time.month'

During handling of the above exception, another exception occurred:

Traceback (most recent call last):
  File "/g/data/e14/as3189/OFAM/scripts/create_file_ofam_EUC_anom_std.py", line 43, in <module>
    ds = xr.open_mfdataset(files, combine='by_coords', concat_dim="Time",
  File "/g/data3/hh5/public/apps/miniconda3/envs/analysis3-21.01/lib/python3.8/site-packages/xarray/backends/api.py", line 956, in open_mfdataset
    datasets, file_objs = dask.compute(datasets, file_objs)
  File "/g/data3/hh5/public/apps/miniconda3/envs/analysis3-21.01/lib/python3.8/site-packages/dask/base.py", line 563, in compute
    results = schedule(dsk, keys, **kwargs)
  File "/g/data3/hh5/public/apps/miniconda3/envs/analysis3-21.01/lib/python3.8/site-packages/dask/threaded.py", line 76, in get
    results = get_async(
  File "/g/data3/hh5/public/apps/miniconda3/envs/analysis3-21.01/lib/python3.8/site-packages/dask/local.py", line 487, in get_async
    raise_exception(exc, tb)
  File "/g/data3/hh5/public/apps/miniconda3/envs/analysis3-21.01/lib/python3.8/site-packages/dask/local.py", line 317, in reraise
    raise exc
  File "/g/data3/hh5/public/apps/miniconda3/envs/analysis3-21.01/lib/python3.8/site-packages/dask/local.py", line 222, in execute_task
    result = _execute_task(task, data)
  File "/g/data3/hh5/public/apps/miniconda3/envs/analysis3-21.01/lib/python3.8/site-packages/dask/core.py", line 121, in _execute_task
    return func(*(_execute_task(a, cache) for a in args))
  File "/g/data/e14/as3189/OFAM/scripts/create_file_ofam_EUC_anom_std.py", line 37, in premeansnip
    ds = ds.groupby('Time.month') - clim.groupby('Time.month').mean('Time', keep_attrs=True).compute()
  File "/g/data3/hh5/public/apps/miniconda3/envs/analysis3-21.01/lib/python3.8/site-packages/xarray/core/common.py", line 696, in groupby
    return self._groupby_cls(
  File "/g/data3/hh5/public/apps/miniconda3/envs/analysis3-21.01/lib/python3.8/site-packages/xarray/core/groupby.py", line 315, in __init__
    group = obj[group]
  File "/g/data3/hh5/public/apps/miniconda3/envs/analysis3-21.01/lib/python3.8/site-packages/xarray/core/dataset.py", line 1359, in __getitem__
    return self._construct_dataarray(key)
  File "/g/data3/hh5/public/apps/miniconda3/envs/analysis3-21.01/lib/python3.8/site-packages/xarray/core/dataset.py", line 1261, in _construct_dataarray
    _, name, variable = _get_virtual_variable(
  File "/g/data3/hh5/public/apps/miniconda3/envs/analysis3-21.01/lib/python3.8/site-packages/xarray/core/dataset.py", line 171, in _get_virtual_variable
    ref_var = variables[ref_name]
KeyError: 'Time'
Traceback (most recent call last):
  File "/g/data3/hh5/public/apps/miniconda3/envs/analysis3-21.01/lib/python3.8/site-packages/xarray/core/dataset.py", line 1259, in _construct_dataarray
    variable = self._variables[name]
KeyError: 'Time.month'

During handling of the above exception, another exception occurred:

Traceback (most recent call last):
  File "/g/data/e14/as3189/OFAM/scripts/create_file_ofam_EUC_anom_std.py", line 43, in <module>
    ds = xr.open_mfdataset(files, combine='by_coords', concat_dim="Time",
  File "/g/data3/hh5/public/apps/miniconda3/envs/analysis3-21.01/lib/python3.8/site-packages/xarray/backends/api.py", line 956, in open_mfdataset
    datasets, file_objs = dask.compute(datasets, file_objs)
  File "/g/data3/hh5/public/apps/miniconda3/envs/analysis3-21.01/lib/python3.8/site-packages/dask/base.py", line 563, in compute
    results = schedule(dsk, keys, **kwargs)
  File "/g/data3/hh5/public/apps/miniconda3/envs/analysis3-21.01/lib/python3.8/site-packages/dask/threaded.py", line 76, in get
    results = get_async(
  File "/g/data3/hh5/public/apps/miniconda3/envs/analysis3-21.01/lib/python3.8/site-packages/dask/local.py", line 487, in get_async
    raise_exception(exc, tb)
  File "/g/data3/hh5/public/apps/miniconda3/envs/analysis3-21.01/lib/python3.8/site-packages/dask/local.py", line 317, in reraise
    raise exc
  File "/g/data3/hh5/public/apps/miniconda3/envs/analysis3-21.01/lib/python3.8/site-packages/dask/local.py", line 222, in execute_task
    result = _execute_task(task, data)
  File "/g/data3/hh5/public/apps/miniconda3/envs/analysis3-21.01/lib/python3.8/site-packages/dask/core.py", line 121, in _execute_task
    return func(*(_execute_task(a, cache) for a in args))
  File "/g/data/e14/as3189/OFAM/scripts/create_file_ofam_EUC_anom_std.py", line 37, in premeansnip
    ds = ds.groupby('Time.month') - clim.groupby('Time.month').mean('Time', keep_attrs=True).compute()
  File "/g/data3/hh5/public/apps/miniconda3/envs/analysis3-21.01/lib/python3.8/site-packages/xarray/core/common.py", line 696, in groupby
    return self._groupby_cls(
  File "/g/data3/hh5/public/apps/miniconda3/envs/analysis3-21.01/lib/python3.8/site-packages/xarray/core/groupby.py", line 315, in __init__
    group = obj[group]
  File "/g/data3/hh5/public/apps/miniconda3/envs/analysis3-21.01/lib/python3.8/site-packages/xarray/core/dataset.py", line 1359, in __getitem__
    return self._construct_dataarray(key)
  File "/g/data3/hh5/public/apps/miniconda3/envs/analysis3-21.01/lib/python3.8/site-packages/xarray/core/dataset.py", line 1261, in _construct_dataarray
    _, name, variable = _get_virtual_variable(
  File "/g/data3/hh5/public/apps/miniconda3/envs/analysis3-21.01/lib/python3.8/site-packages/xarray/core/dataset.py", line 171, in _get_virtual_variable
    ref_var = variables[ref_name]
KeyError: 'Time'
Traceback (most recent call last):
  File "/g/data3/hh5/public/apps/miniconda3/envs/analysis3-21.01/lib/python3.8/site-packages/xarray/core/dataset.py", line 1259, in _construct_dataarray
    variable = self._variables[name]
KeyError: 'Time.month'

During handling of the above exception, another exception occurred:

Traceback (most recent call last):
  File "/g/data/e14/as3189/OFAM/scripts/create_file_ofam_EUC_anom_std.py", line 43, in <module>
    ds = xr.open_mfdataset(files, combine='by_coords', concat_dim="Time",
  File "/g/data3/hh5/public/apps/miniconda3/envs/analysis3-21.01/lib/python3.8/site-packages/xarray/backends/api.py", line 956, in open_mfdataset
    datasets, file_objs = dask.compute(datasets, file_objs)
  File "/g/data3/hh5/public/apps/miniconda3/envs/analysis3-21.01/lib/python3.8/site-packages/dask/base.py", line 563, in compute
    results = schedule(dsk, keys, **kwargs)
  File "/g/data3/hh5/public/apps/miniconda3/envs/analysis3-21.01/lib/python3.8/site-packages/dask/threaded.py", line 76, in get
    results = get_async(
  File "/g/data3/hh5/public/apps/miniconda3/envs/analysis3-21.01/lib/python3.8/site-packages/dask/local.py", line 487, in get_async
    raise_exception(exc, tb)
  File "/g/data3/hh5/public/apps/miniconda3/envs/analysis3-21.01/lib/python3.8/site-packages/dask/local.py", line 317, in reraise
    raise exc
  File "/g/data3/hh5/public/apps/miniconda3/envs/analysis3-21.01/lib/python3.8/site-packages/dask/local.py", line 222, in execute_task
    result = _execute_task(task, data)
  File "/g/data3/hh5/public/apps/miniconda3/envs/analysis3-21.01/lib/python3.8/site-packages/dask/core.py", line 121, in _execute_task
    return func(*(_execute_task(a, cache) for a in args))
  File "/g/data/e14/as3189/OFAM/scripts/create_file_ofam_EUC_anom_std.py", line 37, in premeansnip
    ds = ds.groupby('Time.month') - clim.groupby('Time.month').mean('Time', keep_attrs=True).compute()
  File "/g/data3/hh5/public/apps/miniconda3/envs/analysis3-21.01/lib/python3.8/site-packages/xarray/core/common.py", line 696, in groupby
    return self._groupby_cls(
  File "/g/data3/hh5/public/apps/miniconda3/envs/analysis3-21.01/lib/python3.8/site-packages/xarray/core/groupby.py", line 315, in __init__
    group = obj[group]
  File "/g/data3/hh5/public/apps/miniconda3/envs/analysis3-21.01/lib/python3.8/site-packages/xarray/core/dataset.py", line 1359, in __getitem__
    return self._construct_dataarray(key)
  File "/g/data3/hh5/public/apps/miniconda3/envs/analysis3-21.01/lib/python3.8/site-packages/xarray/core/dataset.py", line 1261, in _construct_dataarray
    _, name, variable = _get_virtual_variable(
  File "/g/data3/hh5/public/apps/miniconda3/envs/analysis3-21.01/lib/python3.8/site-packages/xarray/core/dataset.py", line 171, in _get_virtual_variable
    ref_var = variables[ref_name]
KeyError: 'Time'
Traceback (most recent call last):
  File "/g/data3/hh5/public/apps/miniconda3/envs/analysis3-21.01/lib/python3.8/site-packages/xarray/core/dataset.py", line 1259, in _construct_dataarray
    variable = self._variables[name]
KeyError: 'Time.month'

During handling of the above exception, another exception occurred:

Traceback (most recent call last):
  File "/g/data/e14/as3189/OFAM/scripts/create_file_ofam_EUC_anom_std.py", line 43, in <module>
    ds = xr.open_mfdataset(files, combine='by_coords', concat_dim="Time",
  File "/g/data3/hh5/public/apps/miniconda3/envs/analysis3-21.01/lib/python3.8/site-packages/xarray/backends/api.py", line 956, in open_mfdataset
    datasets, file_objs = dask.compute(datasets, file_objs)
  File "/g/data3/hh5/public/apps/miniconda3/envs/analysis3-21.01/lib/python3.8/site-packages/dask/base.py", line 563, in compute
    results = schedule(dsk, keys, **kwargs)
  File "/g/data3/hh5/public/apps/miniconda3/envs/analysis3-21.01/lib/python3.8/site-packages/dask/threaded.py", line 76, in get
    results = get_async(
  File "/g/data3/hh5/public/apps/miniconda3/envs/analysis3-21.01/lib/python3.8/site-packages/dask/local.py", line 487, in get_async
    raise_exception(exc, tb)
  File "/g/data3/hh5/public/apps/miniconda3/envs/analysis3-21.01/lib/python3.8/site-packages/dask/local.py", line 317, in reraise
    raise exc
  File "/g/data3/hh5/public/apps/miniconda3/envs/analysis3-21.01/lib/python3.8/site-packages/dask/local.py", line 222, in execute_task
    result = _execute_task(task, data)
  File "/g/data3/hh5/public/apps/miniconda3/envs/analysis3-21.01/lib/python3.8/site-packages/dask/core.py", line 121, in _execute_task
    return func(*(_execute_task(a, cache) for a in args))
  File "/g/data/e14/as3189/OFAM/scripts/create_file_ofam_EUC_anom_std.py", line 37, in premeansnip
    ds = ds.groupby('Time.month') - clim.groupby('Time.month').mean('Time', keep_attrs=True).compute()
  File "/g/data3/hh5/public/apps/miniconda3/envs/analysis3-21.01/lib/python3.8/site-packages/xarray/core/common.py", line 696, in groupby
    return self._groupby_cls(
  File "/g/data3/hh5/public/apps/miniconda3/envs/analysis3-21.01/lib/python3.8/site-packages/xarray/core/groupby.py", line 315, in __init__
    group = obj[group]
  File "/g/data3/hh5/public/apps/miniconda3/envs/analysis3-21.01/lib/python3.8/site-packages/xarray/core/dataset.py", line 1359, in __getitem__
    return self._construct_dataarray(key)
  File "/g/data3/hh5/public/apps/miniconda3/envs/analysis3-21.01/lib/python3.8/site-packages/xarray/core/dataset.py", line 1261, in _construct_dataarray
    _, name, variable = _get_virtual_variable(
  File "/g/data3/hh5/public/apps/miniconda3/envs/analysis3-21.01/lib/python3.8/site-packages/xarray/core/dataset.py", line 171, in _get_virtual_variable
    ref_var = variables[ref_name]
KeyError: 'Time'
--------------------------------------------------------------------------
Primary job  terminated normally, but 1 process returned
a non-zero exit code. Per user-direction, the job has been aborted.
--------------------------------------------------------------------------
--------------------------------------------------------------------------
mpirun detected that one or more processes exited with non-zero status, thus causing
the job to be terminated. The first process to do so was:

  Process name: [[37106,1],5]
  Exit code:    1
--------------------------------------------------------------------------
