plx_hist_165_v1r00: Updating particle source in file.
plx_hist_165_v1r00: Saving updated file.
Traceback (most recent call last):
  File "/g/data/hh5/public/apps/miniconda3/envs/analysis3-21.10/lib/python3.9/site-packages/xarray/backends/file_manager.py", line 199, in _acquire_with_cache_info
    file = self._cache[self._key]
  File "/g/data/hh5/public/apps/miniconda3/envs/analysis3-21.10/lib/python3.9/site-packages/xarray/backends/lru_cache.py", line 53, in __getitem__
    value = self._cache[key]
KeyError: [<class 'netCDF4._netCDF4.Dataset'>, ('/g/data/e14/as3189/stellema/plx/data/plx/plx_hist_165_v1r00.nc',), 'a', (('clobber', True), ('diskless', False), ('format', 'NETCDF4'), ('persist', False))]

During handling of the above exception, another exception occurred:

Traceback (most recent call last):
  File "/g/data/e14/as3189/stellema/plx/scripts/plx_sources.py", line 335, in <module>
    merge_plx_source_files(args.lon, args.exp, v=1)
  File "/g/data/e14/as3189/stellema/plx/scripts/tools.py", line 142, in timed
    result = method(*args, **kw)
  File "/g/data/e14/as3189/stellema/plx/scripts/plx_sources.py", line 306, in merge_plx_source_files
    plx_source_file(lon, exp, v, r)
  File "/g/data/e14/as3189/stellema/plx/scripts/tools.py", line 142, in timed
    result = method(*args, **kw)
  File "/g/data/e14/as3189/stellema/plx/scripts/plx_sources.py", line 252, in plx_source_file
    update_formatted_file_sources(lon, exp, v, r)
  File "/g/data/e14/as3189/stellema/plx/scripts/tools.py", line 142, in timed
    result = method(*args, **kw)
  File "/g/data/e14/as3189/stellema/plx/scripts/plx_sources.py", line 109, in update_formatted_file_sources
    ds_full.to_netcdf(xid, encoding=encoding, compute=True)
  File "/g/data/hh5/public/apps/miniconda3/envs/analysis3-21.10/lib/python3.9/site-packages/xarray/core/dataset.py", line 1902, in to_netcdf
    return to_netcdf(
  File "/g/data/hh5/public/apps/miniconda3/envs/analysis3-21.10/lib/python3.9/site-packages/xarray/backends/api.py", line 1055, in to_netcdf
    store = store_open(target, mode, format, group, **kwargs)
  File "/g/data/hh5/public/apps/miniconda3/envs/analysis3-21.10/lib/python3.9/site-packages/xarray/backends/netCDF4_.py", line 379, in open
    return cls(manager, group=group, mode=mode, lock=lock, autoclose=autoclose)
  File "/g/data/hh5/public/apps/miniconda3/envs/analysis3-21.10/lib/python3.9/site-packages/xarray/backends/netCDF4_.py", line 327, in __init__
    self.format = self.ds.data_model
  File "/g/data/hh5/public/apps/miniconda3/envs/analysis3-21.10/lib/python3.9/site-packages/xarray/backends/netCDF4_.py", line 388, in ds
    return self._acquire()
  File "/g/data/hh5/public/apps/miniconda3/envs/analysis3-21.10/lib/python3.9/site-packages/xarray/backends/netCDF4_.py", line 382, in _acquire
    with self._manager.acquire_context(needs_lock) as root:
  File "/g/data/hh5/public/apps/miniconda3/envs/analysis3-21.10/lib/python3.9/contextlib.py", line 119, in __enter__
    return next(self.gen)
  File "/g/data/hh5/public/apps/miniconda3/envs/analysis3-21.10/lib/python3.9/site-packages/xarray/backends/file_manager.py", line 187, in acquire_context
    file, cached = self._acquire_with_cache_info(needs_lock)
  File "/g/data/hh5/public/apps/miniconda3/envs/analysis3-21.10/lib/python3.9/site-packages/xarray/backends/file_manager.py", line 205, in _acquire_with_cache_info
    file = self._opener(*self._args, **kwargs)
  File "src/netCDF4/_netCDF4.pyx", line 2330, in netCDF4._netCDF4.Dataset.__init__
  File "src/netCDF4/_netCDF4.pyx", line 1948, in netCDF4._netCDF4._ensure_nc_success
PermissionError: [Errno 13] Permission denied: b'/g/data/e14/as3189/stellema/plx/data/plx/plx_hist_165_v1r00.nc'
